Workbook

Sheet STOCK_SISTEMA
A1: Referencia Interna | B1: Producto | C1: Número de lote | D1: Fecha de caducidad | E1: Lugar | F1: Cantidad inventariada | G1: Unidad de Medida | H1: Código de barras producto | I1: Clave de búsqueda | J1: Activo
A2: EE10005 | B2: [EE10005] CAJA MASTER TIYAPUY CAFÉ # 5 X UND | C2: 16/25 | D2: 46387 | E2: SF-03/Materiales | F2: 80 | G2: Unidades | I2: =IF(A2="","",A2&"|"&C2) -> EE10005|16/25 | J2: =IF(A2<>"","SÍ","NO") -> SÍ
A3: EE10073 | B3: [EE10073] CINTA DE EMBALAJE 2" X 110 YD X ROLLO | E3: SF-03/Materiales | F3: 462.7654 | G3: Unidades | I3: =IF(A3="","",A3&"|"&C3) -> EE10073| | J3: =IF(A3<>"","SÍ","NO") -> SÍ
A4: EE10072 | B4: [EE10072] ETIQUETA BLANCA CAJA TT-50MMx100MM 1C-T1x1000 | E4: SF-03/Materiales | F4: 223 | G4: Unidades | I4: =IF(A4="","",A4&"|"&C4) -> EE10072| | J4: =IF(A4<>"","SÍ","NO") -> SÍ
A5: EE10071 | B5: [EE10071] ETIQUETA DE FECHAS TT-17 MMx23MM X ROLLO | E5: SF-03/Materiales | F5: 16 | G5: Unidades | I5: =IF(A5="","",A5&"|"&C5) -> EE10071| | J5: =IF(A5<>"","SÍ","NO") -> SÍ
A6: EE10076 | B6: [EE10076] RIBBON 110MMx300MTS NEGRO CERA OUT | E6: SF-03/Materiales | F6: 86.6136 | G6: Unidades | I6: =IF(A6="","",A6&"|"&C6) -> EE10076| | J6: =IF(A6<>"","SÍ","NO") -> SÍ
A7: EE10078 | B7: [EE10078] CINTA 1" X 110 YD TRANSPARENTE X ROLLO | E7: SF-03/Materiales | F7: 156.658 | G7: Unidades | I7: =IF(A7="","",A7&"|"&C7) -> EE10078| | J7: =IF(A7<>"","SÍ","NO") -> SÍ
A8: EE10115 | B8: [EE10115] CINTA CODIFICADORA TERMOIMPRESIÓN X ROLLO 34MM X 600M | E8: SF-03/Materiales | F8: 2.8078 | G8: Unidades | I8: =IF(A8="","",A8&"|"&C8) -> EE10115| | J8: =IF(A8<>"","SÍ","NO") -> SÍ
A9: EE10079 | B9: [EE10079] CINTILLOS TIRA 1.7CM X 43.5CM X UND | E9: SF-03/Materiales | F9: 690000 | G9: Unidades | I9: =IF(A9="","",A9&"|"&C9) -> EE10079| | J9: =IF(A9<>"","SÍ","NO") -> SÍ
A10: EE10120 | B10: [EE10120] CINTILLOS TIRA 1.7CM X 50 CM X UND | E10: SF-03/Materiales | F10: 20000 | G10: Unidades | I10: =IF(A10="","",A10&"|"&C10) -> EE10120| | J10: =IF(A10<>"","SÍ","NO") -> SÍ
A11: EE10010 | B11: [EE10010] CAJITA CAFÉ 86 PTOS ORG X UND | C11: INFORME 20 | D11: 46387.735 | E11: SF-03/Materiales | F11: 800 | G11: Unidades | I11: =IF(A11="","",A11&"|"&C11) -> EE10010|INFORME 20 | J11: =IF(A11<>"","SÍ","NO") -> SÍ
A12: EE10010 | B12: [EE10010] CAJITA CAFÉ 86 PTOS ORG X UND | C12: INFORME 31 | D12: 46387.676 | E12: SF-03/Materiales | F12: 600 | G12: Unidades | I12: =IF(A12="","",A12&"|"&C12) -> EE10010|INFORME 31 | J12: =IF(A12<>"","SÍ","NO") -> SÍ
A13: EE10008 | B13: [EE10008] CAJA MASTER TIYAPUY QUINUA GRANO # 8 X UND | C13: INFORME 33 | E13: SF-03/Materiales | F13: 625 | G13: Unidades | I13: =IF(A13="","",A13&"|"&C13) -> EE10008|INFORME 33 | J13: =IF(A13<>"","SÍ","NO") -> SÍ
A14: EE10137 | B14: [EE10137] CINTA CODIFICADORA TERMOIMPRESIÓN X ROLLO 33MM X 700M | E14: SF-03/Materiales | F14: 25.807 | G14: Unidades | I14: =IF(A14="","",A14&"|"&C14) -> EE10137| | J14: =IF(A14<>"","SÍ","NO") -> SÍ
A15: EE10140 | B15: [EE10140] LAMINA TIYAPUY NATIVA MIX 160GR ESPAÑA X KG | C15: INFORME 39 | D15: 46203.696 | E15: SF-03/Materiales | F15: 282.72 | G15: Kilogramo | I15: =IF(A15="","",A15&"|"&C15) -> EE10140|INFORME 39 | J15: =IF(A15<>"","SÍ","NO") -> SÍ
A16: EE10141 | B16: [EE10141] LAMINA TIYAPUY AMARILLA 160GR ESPAÑA X KG | C16: INFORME 21 | D16: 45771.696 | E16: SF-03/Materiales | F16: 438.2 | G16: Kilogramo | I16: =IF(A16="","",A16&"|"&C16) -> EE10141|INFORME 21 | J16: =IF(A16<>"","SÍ","NO") -> SÍ
A17: EE10074 | B17: [EE10074] CINTAS SNACK 36MM X 200 M X ROLLO | E17: SF-03/Materiales | F17: 800.336 | G17: Unidades | I17: =IF(A17="","",A17&"|"&C17) -> EE10074| | J17: =IF(A17<>"","SÍ","NO") -> SÍ
A18: EE10154 | B18: [EE10154] BOLSA DE POLIETILENO ANCHO 26"x ALTO 59"x1.5 MIC ALTA NATURAL C/FUELLE 2" | C18: LOTE 509 | D18: 46037.488 | E18: SF-03/Materiales | F18: 1450 | G18: Unidades | I18: =IF(A18="","",A18&"|"&C18) -> EE10154|LOTE 509 | J18: =IF(A18<>"","SÍ","NO") -> SÍ
A19: EE10056 | B19: [EE10056] BOLSA TIYAPUY SUPERPACK 142GR X UND | C19: 02/25 | E19: SF-03/Materiales | F19: 300 | G19: Unidades | I19: =IF(A19="","",A19&"|"&C19) -> EE10056|02/25 | J19: =IF(A19<>"","SÍ","NO") -> SÍ
A20: EE10056 | B20: [EE10056] BOLSA TIYAPUY SUPERPACK 142GR X UND | C20: 01/25 | E20: SF-03/Materiales | F20: 5500 | G20: Unidades | I20: =IF(A20="","",A20&"|"&C20) -> EE10056|01/25 | J20: =IF(A20<>"","SÍ","NO") -> SÍ
A21: EE10159 | B21: [EE10159] LAMINA RIKY TOK 155 GR PAPAS HILO X KG | C21: INFORME 02/25 | E21: SF-03/Materiales | F21: 1085 | G21: Kilogramo | I21: =IF(A21="","",A21&"|"&C21) -> EE10159|INFORME 02/25 | J21: =IF(A21<>"","SÍ","NO") -> SÍ
A22: EE10165 | B22: [EE10165] PALLET LIVIANA 1.2MX1M EXPORTACION | E22: SF-03/Materiales | F22: 194.4 | G22: Unidades | I22: =IF(A22="","",A22&"|"&C22) -> EE10165| | J22: =IF(A22<>"","SÍ","NO") -> SÍ
A23: EE10154 | B23: [EE10154] BOLSA DE POLIETILENO ANCHO 26"x ALTO 59"x1.5 MIC ALTA NATURAL C/FUELLE 2" | C23: LOTE 692 | E23: SF-03/Materiales | F23: 3200 | G23: Unidades | I23: =IF(A23="","",A23&"|"&C23) -> EE10154|LOTE 692 | J23: =IF(A23<>"","SÍ","NO") -> SÍ
A24: EE10177 | B24: [EE10177] PALLET EURO LIVIANA 0.8MX1.2M EXPORTACION | E24: SF-03/Materiales | F24: 45 | G24: Unidades | I24: =IF(A24="","",A24&"|"&C24) -> EE10177| | J24: =IF(A24<>"","SÍ","NO") -> SÍ
A25: EE10149-2 | B25: [EE10149-2] STICKERS RIKYTOK PARA LAMINA CONG SIN IMPRESION PEBD 1KG | E25: SF-03/Materiales | F25: 20350 | G25: Unidades | I25: =IF(A25="","",A25&"|"&C25) -> EE10149-2| | J25: =IF(A25<>"","SÍ","NO") -> SÍ
A26: EE10146 | B26: [EE10146] LAMINA TIYAPUY AMARILLA PICANTE 142GR CONV MEXICO X KG | C26: INFORME 02/25 | D26: 46137.619 | E26: SF-03/Materiales | F26: 351.7024 | G26: Kilogramo | I26: =IF(A26="","",A26&"|"&C26) -> EE10146|INFORME 02/25 | J26: =IF(A26<>"","SÍ","NO") -> SÍ
A27: EE10088-1 | B27: [EE10088-1] LAMINA TIYAPUY NATIVA MIX 40GR ORG MEXICO X KG | C27: INFORME 05/25 | D27: 46203.624 | E27: SF-03/Materiales | F27: 53.75 | G27: Kilogramo | I27: =IF(A27="","",A27&"|"&C27) -> EE10088-1|INFORME 05/25 | J27: =IF(A27<>"","SÍ","NO") -> SÍ
A28: EE10047 | B28: [EE10047] LAMINA RIKY TOK 30 GR ONDA PICANTE X KG | C28: INFORME 05/25 | D28: 45835.699 | E28: SF-03/Cuarentena | F28: 52 | G28: Kilogramo | I28: =IF(A28="","",A28&"|"&C28) -> EE10047|INFORME 05/25 | J28: =IF(A28<>"","SÍ","NO") -> SÍ
A29: EE10004 | B29: [EE10004] CAJA MASTER TIYAPUY AMAZON # 4 X UND | C29: LT-SF-AGR | D29: 46387 | E29: SF-03/Materiales | F29: 2625 | G29: Unidades | I29: =IF(A29="","",A29&"|"&C29) -> EE10004|LT-SF-AGR | J29: =IF(A29<>"","SÍ","NO") -> SÍ
A30: EE10092 | B30: [EE10092] BOLSA LAMINADA CAFÉ UNAKA C/FUELLE C/SELLOS 200g | C30: INFORME 10 | D30: 46387.792 | E30: SF-03/Materiales | F30: 333 | G30: Unidades | I30: =IF(A30="","",A30&"|"&C30) -> EE10092|INFORME 10 | J30: =IF(A30<>"","SÍ","NO") -> SÍ
A31: EE10092 | B31: [EE10092] BOLSA LAMINADA CAFÉ UNAKA C/FUELLE C/SELLOS 200g | C31: INFORME 11 | D31: 46387.792 | E31: SF-03/Materiales | F31: 2200 | G31: Unidades | I31: =IF(A31="","",A31&"|"&C31) -> EE10092|INFORME 11 | J31: =IF(A31<>"","SÍ","NO") -> SÍ
A32: EE10092 | B32: [EE10092] BOLSA LAMINADA CAFÉ UNAKA C/FUELLE C/SELLOS 200g | C32: INFORME 8 | D32: 46387.792 | E32: SF-03/Materiales | F32: 2800 | G32: Unidades | I32: =IF(A32="","",A32&"|"&C32) -> EE10092|INFORME 8 | J32: =IF(A32<>"","SÍ","NO") -> SÍ
A33: EE10158 | B33: [EE10158] LAMINA RIKY TOK 45 GR PAPAS HILO X KG | C33: INFORME 04/25 | D33: 46152.412 | E33: SF-03/Materiales | F33: 188.877 | G33: Kilogramo | I33: =IF(A33="","",A33&"|"&C33) -> EE10158|INFORME 04/25 | J33: =IF(A33<>"","SÍ","NO") -> SÍ
A34: EE10181 | B34: [EE10181] STICKERS TIYAPUY PARA LAMINA CONG SIN IMPRESION PEBD 2.5KG | C34: INFORME 21/25 | D34: 46387.52 | E34: SF-03/Materiales | F34: 15000 | G34: Unidades | I34: =IF(A34="","",A34&"|"&C34) -> EE10181|INFORME 21/25 | J34: =IF(A34<>"","SÍ","NO") -> SÍ
A35: EE10158 | B35: [EE10158] LAMINA RIKY TOK 45 GR PAPAS HILO X KG | C35: INFORME 06/25 | D35: 46162.962 | E35: SF-03/Materiales | F35: 667.14 | G35: Kilogramo | I35: =IF(A35="","",A35&"|"&C35) -> EE10158|INFORME 06/25 | J35: =IF(A35<>"","SÍ","NO") -> SÍ
A36: EE10121 | B36: [EE10121] LAMINA TIYAPUY AMARILLA 142 GR CONVENCIONAL X KG | C36: INFORME 10/25 | D36: 46169.474 | E36: SF-03/Materiales | F36: 337.29 | G36: Kilogramo | I36: =IF(A36="","",A36&"|"&C36) -> EE10121|INFORME 10/25 | J36: =IF(A36<>"","SÍ","NO") -> SÍ
A37: EE10097 | B37: [EE10097] PALLET EAN 1.2MX1M EXPORTACION | E37: SF-03/Materiales | F37: 76 | G37: Unidades | I37: =IF(A37="","",A37&"|"&C37) -> EE10097| | J37: =IF(A37<>"","SÍ","NO") -> SÍ
A38: EE10025 | B38: [EE10025] LAMINA TIYAPUY NATIVA MIX 30GR CONVENCIONAL X KG | C38: INFORME 03/25 | D38: 45921.696 | E38: SF-03/Cuarentena | F38: 4 | G38: Kilogramo | I38: =IF(A38="","",A38&"|"&C38) -> EE10025|INFORME 03/25 | J38: =IF(A38<>"","SÍ","NO") -> SÍ
A39: EE10047 | B39: [EE10047] LAMINA RIKY TOK 30 GR ONDA PICANTE X KG | C39: INFORME 06/25 | D39: 45855.7 | E39: SF-03/Cuarentena | F39: 199.4 | G39: Kilogramo | I39: =IF(A39="","",A39&"|"&C39) -> EE10047|INFORME 06/25 | J39: =IF(A39<>"","SÍ","NO") -> SÍ
A40: EE10158 | B40: [EE10158] LAMINA RIKY TOK 45 GR PAPAS HILO X KG | C40: INFORME 07/25 | D40: 46001.465 | E40: SF-03/Materiales | F40: 861.73 | G40: Kilogramo | I40: =IF(A40="","",A40&"|"&C40) -> EE10158|INFORME 07/25 | J40: =IF(A40<>"","SÍ","NO") -> SÍ
...

Sheet UBICACIONES
A1: Código ubicación | B1: Nombre ubicación | C1: Código de barras | D1: Activa | E1: Observaciones
A2: CONTROL_CALIDAD_0001 | B2: SF-03/Control calidad | C2: CONTROL_CALIDAD_0001 | D2: SÍ | E2: Ubicación interna
A3: SF-03/Cuarentena | B3: SF-03/Cuarentena | C3: SF-03/Cuarentena | D3: SÍ | E3: Ubicación interna
A4: Cuarentena_PT-001 | B4: SF-03/Cuarentena_PT | C4: Cuarentena_PT-001 | D4: SÍ | E4: Ubicación interna
A5: SF-03/Desecho | B5: SF-03/Desecho | C5: SF-03/Desecho | D5: SÍ | E5: Ubicación interna
A6: SF-03/Desmedro Otros | B6: SF-03/Desmedro Otros | C6: SF-03/Desmedro Otros | D6: SÍ | E6: Ubicación interna
A7: WH-INPUT | B7: SF-03/Entrada | C7: WH-INPUT | D7: SÍ | E7: Ubicación interna
A8: SF-03/Materiales | B8: SF-03/Materiales | C8: SF-03/Materiales | D8: SÍ | E8: Ubicación interna
A9: SF-03/Merma | B9: SF-03/Merma | C9: SF-03/Merma | D9: SÍ | E9: Ubicación interna
A10: SF-03/No conforme | B10: SF-03/No conforme | C10: SF-03/No conforme | D10: SÍ | E10: Ubicación interna
A11: SF-03/PT | B11: SF-03/PT | C11: SF-03/PT | D11: SÍ | E11: Ubicación interna
A12: SF-03/PT/DESPACHO | B12: SF-03/PT/DESPACHO | C12: SF-03/PT/DESPACHO | D12: SÍ | E12: Ubicación interna
... A1659: SF-03/Repuestos | B1659: SF-03/Repuestos | C1659: SF-03/Repuestos | D1659: SÍ | E1659: Ubicación interna
A1660: SF-03/Salida | B1660: SF-03/Salida | C1660: SF-03/Salida | E1660: Ubicación interna

Sheet CONTEOS
A1: ID conteo | B1: Fecha y hora | C1: Usuario | D1: Tipo identificación | E1: Texto OCR o código leído | F1: Referencia interna | G1: Producto | H1: Lote | I1: Fecha de vencimiento | J1: Unidad de medida | K1: Stock sistema | L1: Ubicación física | M1: Código ubicación | N1: Cantidad física | O1: Diferencia acumulada | P1: Estado | Q1: Observación | R1: Foto etiqueta

Sheet RESUMEN_AJUSTE
A1: Referencia interna | B1: Producto | C1: Lote | D1: Fecha de vencimiento | E1: Lugar sistema | F1: Unidad | G1: Stock sistema | H1: Stock físico | I1: Diferencia | J1: Estado | K1: Observación
A2: =STOCK_SISTEMA!A2 -> EE10005 | B2: =STOCK_SISTEMA!B2 -> [EE10005] CAJA MASTER TIYAPUY CAFÉ # 5 X UND | C2: =IF(STOCK_SISTEMA!C2="","",STOCK_SISTEMA!C2) -> 16/25 | D2: =IF(STOCK_SISTEMA!D2="","",STOCK_SISTEMA!D2) -> 46387 | E2: =STOCK_SISTEMA!E2 -> SF-03/Materiales | F2: =STOCK_SISTEMA!G2 -> Unidades | G2: =STOCK_SISTEMA!F2 -> 80 | H2: =SUMIFS(CONTEOS!$N$2:$N$4000,CONTEOS!$F$2:$F$4000,A2,CONTEOS!$H$2:$H$4000,C2) -> 0 | I2: =H2-G2 -> -80 | J2: =IF(COUNTIFS(CONTEOS!$F$2:$F$4000,A2,CONTEOS!$H$2:$H$4000,C2)=0,"PENDIENTE",IF(I2=0,"CUADRA",IF(I2>0,"SOBRANTE","FALTANTE"))) -> PENDIENTE
A3: =STOCK_SISTEMA!A3 -> EE10073 | B3: =STOCK_SISTEMA!B3 -> [EE10073] CINTA DE EMBALAJE 2" X 110 YD X ROLLO | C3: =IF(STOCK_SISTEMA!C3="","",STOCK_SISTEMA!C3) | D3: =IF(STOCK_SISTEMA!D3="","",STOCK_SISTEMA!D3) | E3: =STOCK_SISTEMA!E3 -> SF-03/Materiales | F3: =STOCK_SISTEMA!G3 -> Unidades | G3: =STOCK_SISTEMA!F3 -> 462.7654 | H3: =SUMIFS(CONTEOS!$N$2:$N$4000,CONTEOS!$F$2:$F$4000,A3,CONTEOS!$H$2:$H$4000,C3) -> 0 | I3: =H3-G3 -> -462.7654 | J3: =IF(COUNTIFS(CONTEOS!$F$2:$F$4000,A3,CONTEOS!$H$2:$H$4000,C3)=0,"PENDIENTE",IF(I3=0,"CUADRA",IF(I3>0,"SOBRANTE","FALTANTE"))) -> PENDIENTE
A4: =STOCK_SISTEMA!A4 -> EE10072 | B4: =STOCK_SISTEMA!B4 -> [EE10072] ETIQUETA BLANCA CAJA TT-50MMx100MM 1C-T1x1000 | C4: =IF(STOCK_SISTEMA!C4="","",STOCK_SISTEMA!C4) | D4: =IF(STOCK_SISTEMA!D4="","",STOCK_SISTEMA!D4) | E4: =STOCK_SISTEMA!E4 -> SF-03/Materiales | F4: =STOCK_SISTEMA!G4 -> Unidades | G4: =STOCK_SISTEMA!F4 -> 223 | H4: =SUMIFS(CONTEOS!$N$2:$N$4000,CONTEOS!$F$2:$F$4000,A4,CONTEOS!$H$2:$H$4000,C4) -> 0 | I4: =H4-G4 -> -223 | J4: =IF(COUNTIFS(CONTEOS!$F$2:$F$4000,A4,CONTEOS!$H$2:$H$4000,C4)=0,"PENDIENTE",IF(I4=0,"CUADRA",IF(I4>0,"SOBRANTE","FALTANTE"))) -> PENDIENTE
A5: =STOCK_SISTEMA!A5 -> EE10071 | B5: =STOCK_SISTEMA!B5 -> [EE10071] ETIQUETA DE FECHAS TT-17 MMx23MM X ROLLO | C5: =IF(STOCK_SISTEMA!C5="","",STOCK_SISTEMA!C5) | D5: =IF(STOCK_SISTEMA!D5="","",STOCK_SISTEMA!D5) | E5: =STOCK_SISTEMA!E5 -> SF-03/Materiales | F5: =STOCK_SISTEMA!G5 -> Unidades | G5: =STOCK_SISTEMA!F5 -> 16 | H5: =SUMIFS(CONTEOS!$N$2:$N$4000,CONTEOS!$F$2:$F$4000,A5,CONTEOS!$H$2:$H$4000,C5) -> 0 | I5: =H5-G5 -> -16 | J5: =IF(COUNTIFS(CONTEOS!$F$2:$F$4000,A5,CONTEOS!$H$2:$H$4000,C5)=0,"PENDIENTE",IF(I5=0,"CUADRA",IF(I5>0,"SOBRANTE","FALTANTE"))) -> PENDIENTE
A6: =STOCK_SISTEMA!A6 -> EE10076 | B6: =STOCK_SISTEMA!B6 -> [EE10076] RIBBON 110MMx300MTS NEGRO CERA OUT | C6: =IF(STOCK_SISTEMA!C6="","",STOCK_SISTEMA!C6) | D6: =IF(STOCK_SISTEMA!D6="","",STOCK_SISTEMA!D6) | E6: =STOCK_SISTEMA!E6 -> SF-03/Materiales | F6: =STOCK_SISTEMA!G6 -> Unidades | G6: =STOCK_SISTEMA!F6 -> 86.6136 | H6: =SUMIFS(CONTEOS!$N$2:$N$4000,CONTEOS!$F$2:$F$4000,A6,CONTEOS!$H$2:$H$4000,C6) -> 0 | I6: =H6-G6 -> -86.6136 | J6: =IF(COUNTIFS(CONTEOS!$F$2:$F$4000,A6,CONTEOS!$H$2:$H$4000,C6)=0,"PENDIENTE",IF(I6=0,"CUADRA",IF(I6>0,"SOBRANTE","FALTANTE"))) -> PENDIENTE
A7: =STOCK_SISTEMA!A7 -> EE10078 | B7: =STOCK_SISTEMA!B7 -> [EE10078] CINTA 1" X 110 YD TRANSPARENTE X ROLLO | C7: =IF(STOCK_SISTEMA!C7="","",STOCK_SISTEMA!C7) | D7: =IF(STOCK_SISTEMA!D7="","",STOCK_SISTEMA!D7) | E7: =STOCK_SISTEMA!E7 -> SF-03/Materiales | F7: =STOCK_SISTEMA!G7 -> Unidades | G7: =STOCK_SISTEMA!F7 -> 156.658 | H7: =SUMIFS(CONTEOS!$N$2:$N$4000,CONTEOS!$F$2:$F$4000,A7,CONTEOS!$H$2:$H$4000,C7) -> 0 | I7: =H7-G7 -> -156.658 | J7: =IF(COUNTIFS(CONTEOS!$F$2:$F$4000,A7,CONTEOS!$H$2:$H$4000,C7)=0,"PENDIENTE",IF(I7=0,"CUADRA",IF(I7>0,"SOBRANTE","FALTANTE"))) -> PENDIENTE
A8: =STOCK_SISTEMA!A8 -> EE10115 | B8: =STOCK_SISTEMA!B8 -> [EE10115] CINTA CODIFICADORA TERMOIMPRESIÓN X ROLLO 34MM X 600M | C8: =IF(STOCK_SISTEMA!C8="","",STOCK_SISTEMA!C8) | D8: =IF(STOCK_SISTEMA!D8="","",STOCK_SISTEMA!D8) | E8: =STOCK_SISTEMA!E8 -> SF-03/Materiales | F8: =STOCK_SISTEMA!G8 -> Unidades | G8: =STOCK_SISTEMA!F8 -> 2.8078 | H8: =SUMIFS(CONTEOS!$N$2:$N$4000,CONTEOS!$F$2:$F$4000,A8,CONTEOS!$H$2:$H$4000,C8) -> 0 | I8: =H8-G8 -> -2.8078 | J8: =IF(COUNTIFS(CONTEOS!$F$2:$F$4000,A8,CONTEOS!$H$2:$H$4000,C8)=0,"PENDIENTE",IF(I8=0,"CUADRA",IF(I8>0,"SOBRANTE","FALTANTE"))) -> PENDIENTE
A9: =STOCK_SISTEMA!A9 -> EE10079 | B9: =STOCK_SISTEMA!B9 -> [EE10079] CINTILLOS TIRA 1.7CM X 43.5CM X UND | C9: =IF(STOCK_SISTEMA!C9="","",STOCK_SISTEMA!C9) | D9: =IF(STOCK_SISTEMA!D9="","",STOCK_SISTEMA!D9) | E9: =STOCK_SISTEMA!E9 -> SF-03/Materiales | F9: =STOCK_SISTEMA!G9 -> Unidades | G9: =STOCK_SISTEMA!F9 -> 690000 | H9: =SUMIFS(CONTEOS!$N$2:$N$4000,CONTEOS!$F$2:$F$4000,A9,CONTEOS!$H$2:$H$4000,C9) -> 0 | I9: =H9-G9 -> -690000 | J9: =IF(COUNTIFS(CONTEOS!$F$2:$F$4000,A9,CONTEOS!$H$2:$H$4000,C9)=0,"PENDIENTE",IF(I9=0,"CUADRA",IF(I9>0,"SOBRANTE","FALTANTE"))) -> PENDIENTE
A10: =STOCK_SISTEMA!A10 -> EE10120 | B10: =STOCK_SISTEMA!B10 -> [EE10120] CINTILLOS TIRA 1.7CM X 50 CM X UND | C10: =IF(STOCK_SISTEMA!C10="","",STOCK_SISTEMA!C10) | D10: =IF(STOCK_SISTEMA!D10="","",STOCK_SISTEMA!D10) | E10: =STOCK_SISTEMA!E10 -> SF-03/Materiales | F10: =STOCK_SISTEMA!G10 -> Unidades | G10: =STOCK_SISTEMA!F10 -> 20000 | H10: =SUMIFS(CONTEOS!$N$2:$N$4000,CONTEOS!$F$2:$F$4000,A10,CONTEOS!$H$2:$H$4000,C10) -> 0 | I10: =H10-G10 -> -20000 | J10: =IF(COUNTIFS(CONTEOS!$F$2:$F$4000,A10,CONTEOS!$H$2:$H$4000,C10)=0,"PENDIENTE",IF(I10=0,"CUADRA",IF(I10>0,"SOBRANTE","FALTANTE"))) -> PENDIENTE
A11: =STOCK_SISTEMA!A11 -> EE10010 | B11: =STOCK_SISTEMA!B11 -> [EE10010] CAJITA CAFÉ 86 PTOS ORG X UND | C11: =IF(STOCK_SISTEMA!C11="","",STOCK_SISTEMA!C11) -> INFORME 20 | D11: =IF(STOCK_SISTEMA!D11="","",STOCK_SISTEMA!D11) -> 46387.735 | E11: =STOCK_SISTEMA!E11 -> SF-03/Materiales | F11: =STOCK_SISTEMA!G11 -> Unidades | G11: =STOCK_SISTEMA!F11 -> 800 | H11: =SUMIFS(CONTEOS!$N$2:$N$4000,CONTEOS!$F$2:$F$4000,A11,CONTEOS!$H$2:$H$4000,C11) -> 0 | I11: =H11-G11 -> -800 | J11: =IF(COUNTIFS(CONTEOS!$F$2:$F$4000,A11,CONTEOS!$H$2:$H$4000,C11)=0,"PENDIENTE",IF(I11=0,"CUADRA",IF(I11>0,"SOBRANTE","FALTANTE"))) -> PENDIENTE
A12: =STOCK_SISTEMA!A12 -> EE10010 | B12: =STOCK_SISTEMA!B12 -> [EE10010] CAJITA CAFÉ 86 PTOS ORG X UND | C12: =IF(STOCK_SISTEMA!C12="","",STOCK_SISTEMA!C12) -> INFORME 31 | D12: =IF(STOCK_SISTEMA!D12="","",STOCK_SISTEMA!D12) -> 46387.676 | E12: =STOCK_SISTEMA!E12 -> SF-03/Materiales | F12: =STOCK_SISTEMA!G12 -> Unidades | G12: =STOCK_SISTEMA!F12 -> 600 | H12: =SUMIFS(CONTEOS!$N$2:$N$4000,CONTEOS!$F$2:$F$4000,A12,CONTEOS!$H$2:$H$4000,C12) -> 0 | I12: =H12-G12 -> -600 | J12: =IF(COUNTIFS(CONTEOS!$F$2:$F$4000,A12,CONTEOS!$H$2:$H$4000,C12)=0,"PENDIENTE",IF(I12=0,"CUADRA",IF(I12>0,"SOBRANTE","FALTANTE"))) -> PENDIENTE
A13: =STOCK_SISTEMA!A13 -> EE10008 | B13: =STOCK_SISTEMA!B13 -> [EE10008] CAJA MASTER TIYAPUY QUINUA GRANO # 8 X UND | C13: =IF(STOCK_SISTEMA!C13="","",STOCK_SISTEMA!C13) -> INFORME 33 | D13: =IF(STOCK_SISTEMA!D13="","",STOCK_SISTEMA!D13) | E13: =STOCK_SISTEMA!E13 -> SF-03/Materiales | F13: =STOCK_SISTEMA!G13 -> Unidades | G13: =STOCK_SISTEMA!F13 -> 625 | H13: =SUMIFS(CONTEOS!$N$2:$N$4000,CONTEOS!$F$2:$F$4000,A13,CONTEOS!$H$2:$H$4000,C13) -> 0 | I13: =H13-G13 -> -625 | J13: =IF(COUNTIFS(CONTEOS!$F$2:$F$4000,A13,CONTEOS!$H$2:$H$4000,C13)=0,"PENDIENTE",IF(I13=0,"CUADRA",IF(I13>0,"SOBRANTE","FALTANTE"))) -> PENDIENTE
... A337: =STOCK_SISTEMA!A337 -> MP10030 | B337: =STOCK_SISTEMA!B337 -> [MP10030] ALMIDÓN DE MAIZ X KG | C337: =IF(STOCK_SISTEMA!C337="","",STOCK_SISTEMA!C337) -> INFORME 03/26 | D337: =IF(STOCK_SISTEMA!D337="","",STOCK_SISTEMA!D337) -> 46844.369 | E337: =STOCK_SISTEMA!E337 -> SF-03/Materiales | F337: =STOCK_SISTEMA!G337 -> Kilogramo | G337: =STOCK_SISTEMA!F337 -> 32.255 | H337: =SUMIFS(CONTEOS!$N$2:$N$4000,CONTEOS!$F$2:$F$4000,A337,CONTEOS!$H$2:$H$4000,C337) -> 0 | I337: =H337-G337 -> -32.255 | J337: =IF(COUNTIFS(CONTEOS!$F$2:$F$4000,A337,CONTEOS!$H$2:$H$4000,C337)=0,"PENDIENTE",IF(I337=0,"CUADRA",IF(I337>0,"SOBRANTE","FALTANTE"))) -> PENDIENTE

Sheet INCIDENCIAS
A1: Fecha | B1: Tipo incidencia | C1: Referencia interna | D1: Producto | E1: Lote | F1: Ubicación | G1: Detalle | H1: Estado revisión

Sheet GUIA_USO
A1: APP DE INVENTARIO – GUÍA DE PREPARACIÓN
A3: Paso | B3: Acción
A4: 1 | B4: Suba este archivo a Google Drive y ábralo con Hojas de cálculo de Google.
A5: 2 | B5: Complete Código de barras producto en STOCK_SISTEMA cuando sea diferente de la referencia interna.
A6: 3 | B6: Registre todas las ubicaciones y sus códigos de barras en UBICACIONES.
A7: 4 | B7: La aplicación web guardará una fila por producto, lote y ubicación en CONTEOS.
A8: 5 | B8: RESUMEN_AJUSTE totaliza el conteo por referencia y lote y calcula la diferencia.
A9: 6 | B9: Revise faltantes, sobrantes y datos no reconocidos antes de efectuar ajustes en Odoo.
A10: 7 | B10: No modifique los encabezados: serán utilizados por la aplicación web.
